Workbook

Sheet WBS
A1: № работы | B1: Название работы | C1: Паралл. | D1: BI-разработчик | E1: Backend-разработчик | F1: Data Engineer | G1: DevOps | H1: Pentester | I1: Performance Engineer | J1: QA-инженер | K1: Администратор БД | L1: Архитектор | M1: Архитектор ПО | N1: Архитектор безопасности | O1: Архитектор данных | P1: Инженер БД | Q1: Инженер инфраструктуры | R1: Инженер надежности | S1: Инженер по нагрузке | T1: Инженер развертывания | U1: Интеграционный архитектор | V1: Интеграционный разработчик | W1: Проектный менеджер | X1: Системный аналитик | Y1: Специалист ИБ | Z1: Тестировщик | AA1: Технический писатель | AB1: Стоимость (руб)
A2: 1 | B2: Планирование и анализ | D2: 0 | E2: 0 | F2: 0 | G2: 0 | H2: 0 | I2: 0 | J2: 0 | K2: 0 | L2: 0 | M2: 0 | N2: 0 | O2: 0 | P2: 0 | Q2: 0 | R2: 0 | S2: 0 | T2: 0 | U2: 0 | V2: 0 | W2: 0 | X2: 0 | Y2: 0 | Z2: 0 | AA2: 0 | AB2: 0
A3: 1.1 | B3: Анализ требований и декомпозиция | C3: 🔄 | D3: 0 | E3: 0 | F3: 0 | G3: 0 | H3: 0 | I3: 0 | J3: 0 | K3: 0 | L3: 49 | M3: 0 | N3: 0 | O3: 0 | P3: 0 | Q3: 0 | R3: 0 | S3: 0 | T3: 0 | U3: 0 | V3: 0 | W3: 0 | X3: 49 | Y3: 0 | Z3: 0 | AA3: 0 | AB3: =IF(L3=0,0,L3*VLOOKUP("Архитектор",'Ставки профессий'!$A:$B,2,FALSE))+IF(X3=0,0,X3*VLOOKUP("Системный аналитик",'Ставки профессий'!$A:$B,2,FALSE))
A4: 1.1.1 | B4: Сбор и анализ функциональных требований | C4: 🔄 | D4: 0 | E4: 0 | F4: 0 | G4: 0 | H4: 0 | I4: 0 | J4: 0 | K4: 0 | L4: 0 | M4: 0 | N4: 0 | O4: 0 | P4: 0 | Q4: 0 | R4: 0 | S4: 0 | T4: 0 | U4: 0 | V4: 0 | W4: 0 | X4: 16 | Y4: 0 | Z4: 0 | AA4: 0 | AB4: =IF(X4=0,0,X4*VLOOKUP("Системный аналитик",'Ставки профессий'!$A:$B,2,FALSE))
A5: 1.1.2 | B5: Анализ нефункциональных требований и ограничений | C5: 🔄 | D5: 0 | E5: 0 | F5: 0 | G5: 0 | H5: 0 | I5: 0 | J5: 0 | K5: 0 | L5: 8 | M5: 0 | N5: 0 | O5: 0 | P5: 0 | Q5: 0 | R5: 0 | S5: 0 | T5: 0 | U5: 0 | V5: 0 | W5: 0 | X5: 8 | Y5: 0 | Z5: 0 | AA5: 0 | AB5: =IF(L5=0,0,L5*VLOOKUP("Архитектор",'Ставки профессий'!$A:$B,2,FALSE))+IF(X5=0,0,X5*VLOOKUP("Системный аналитик",'Ставки профессий'!$A:$B,2,FALSE))
A6: 1.1.3 | B6: Формирование структуры ТЗ согласно 644-П | C6: 🔄 | D6: 0 | E6: 0 | F6: 0 | G6: 0 | H6: 0 | I6: 0 | J6: 0 | K6: 0 | L6: 0 | M6: 0 | N6: 0 | O6: 0 | P6: 0 | Q6: 0 | R6: 0 | S6: 0 | T6: 0 | U6: 0 | V6: 0 | W6: 0 | X6: 12 | Y6: 0 | Z6: 0 | AA6: 0 | AB6: =IF(X6=0,0,X6*VLOOKUP("Системный аналитик",'Ставки профессий'!$A:$B,2,FALSE))
A7: 1.1.4 | B7: Разработка разделов ТЗ | D7: 0 | E7: 0 | F7: 0 | G7: 0 | H7: 0 | I7: 0 | J7: 0 | K7: 0 | L7: 14 | M7: 0 | N7: 0 | O7: 0 | P7: 0 | Q7: 0 | R7: 0 | S7: 0 | T7: 0 | U7: 0 | V7: 0 | W7: 0 | X7: 14 | Y7: 0 | Z7: 0 | AA7: 0 | AB7: =IF(L7=0,0,L7*VLOOKUP("Архитектор",'Ставки профессий'!$A:$B,2,FALSE))+IF(X7=0,0,X7*VLOOKUP("Системный аналитик",'Ставки профессий'!$A:$B,2,FALSE))
A8: 1.1.5 | B8: Создание матрицы трассировки требований | D8: 0 | E8: 0 | F8: 0 | G8: 0 | H8: 0 | I8: 0 | J8: 0 | K8: 0 | L8: 0 | M8: 0 | N8: 0 | O8: 0 | P8: 0 | Q8: 0 | R8: 0 | S8: 0 | T8: 0 | U8: 0 | V8: 0 | W8: 0 | X8: 10 | Y8: 0 | Z8: 0 | AA8: 0 | AB8: =IF(X8=0,0,X8*VLOOKUP("Системный аналитик",'Ставки профессий'!$A:$B,2,FALSE))
A9: 1.1.6 | B9: Согласование и финализация ТЗ | D9: 0 | E9: 0 | F9: 0 | G9: 0 | H9: 0 | I9: 0 | J9: 0 | K9: 0 | L9: 8 | M9: 0 | N9: 0 | O9: 0 | P9: 0 | Q9: 0 | R9: 0 | S9: 0 | T9: 0 | U9: 0 | V9: 0 | W9: 0 | X9: 8 | Y9: 0 | Z9: 0 | AA9: 0 | AB9: =IF(L9=0,0,L9*VLOOKUP("Архитектор",'Ставки профессий'!$A:$B,2,FALSE))+IF(X9=0,0,X9*VLOOKUP("Системный аналитик",'Ставки профессий'!$A:$B,2,FALSE))
A10: 1.2 | B10: Планирование инфраструктуры и ресурсов | C10: 🔄 | D10: 0 | E10: 0 | F10: 0 | G10: 0 | H10: 0 | I10: 0 | J10: 0 | K10: 0 | L10: 0 | M10: 0 | N10: 0 | O10: 0 | P10: 0 | Q10: 20 | R10: 0 | S10: 0 | T10: 0 | U10: 0 | V10: 0 | W10: 20 | X10: 0 | Y10: 0 | Z10: 0 | AA10: 0 | AB10: =IF(Q10=0,0,Q10*VLOOKUP("Инженер инфраструктуры",'Ставки профессий'!$A:$B,2,FALSE))+IF(W10=0,0,W10*VLOOKUP("Проектный менеджер",'Ставки профессий'!$A:$B,2,FALSE))
A11: 1.2.1 | B11: Анализ требований к инфраструктуре зон развертывания | C11: 🔄 | D11: 0 | E11: 0 | F11: 0 | G11: 0 | H11: 0 | I11: 0 | J11: 0 | K11: 0 | L11: 0 | M11: 0 | N11: 0 | O11: 0 | P11: 0 | Q11: 4 | R11: 0 | S11: 0 | T11: 0 | U11: 0 | V11: 0 | W11: 0 | X11: 0 | Y11: 0 | Z11: 0 | AA11: 0 | AB11: =IF(Q11=0,0,Q11*VLOOKUP("Инженер инфраструктуры",'Ставки профессий'!$A:$B,2,FALSE))
A12: 1.2.2 | B12: Расчет ресурсов для обеспечения RPO/RTO | D12: 0 | E12: 0 | F12: 0 | G12: 0 | H12: 0 | I12: 0 | J12: 0 | K12: 0 | L12: 0 | M12: 0 | N12: 0 | O12: 0 | P12: 0 | Q12: 12 | R12: 0 | S12: 0 | T12: 0 | U12: 0 | V12: 0 | W12: 0 | X12: 0 | Y12: 0 | Z12: 0 | AA12: 0 | AB12: =IF(Q12=0,0,Q12*VLOOKUP("Инженер инфраструктуры",'Ставки профессий'!$A:$B,2,FALSE))
A13: 1.2.3 | B13: Планирование катастрофоустойчивости | D13: 0 | E13: 0 | F13: 0 | G13: 0 | H13: 0 | I13: 0 | J13: 0 | K13: 0 | L13: 0 | M13: 0 | N13: 0 | O13: 0 | P13: 0 | Q13: 4 | R13: 0 | S13: 0 | T13: 0 | U13: 0 | V13: 0 | W13: 0 | X13: 0 | Y13: 0 | Z13: 0 | AA13: 0 | AB13: =IF(Q13=0,0,Q13*VLOOKUP("Инженер инфраструктуры",'Ставки профессий'!$A:$B,2,FALSE))
A14: 1.2.4 | B14: Составление карты компетенций поддержки | C14: 🔄 | D14: 0 | E14: 0 | F14: 0 | G14: 0 | H14: 0 | I14: 0 | J14: 0 | K14: 0 | L14: 0 | M14: 0 | N14: 0 | O14: 0 | P14: 0 | Q14: 0 | R14: 0 | S14: 0 | T14: 0 | U14: 0 | V14: 0 | W14: 12 | X14: 0 | Y14: 0 | Z14: 0 | AA14: 0 | AB14: =IF(W14=0,0,W14*VLOOKUP("Проектный менеджер",'Ставки профессий'!$A:$B,2,FALSE))
A15: 1.2.5 | B15: Формирование плана инфраструктуры | D15: 0 | E15: 0 | F15: 0 | G15: 0 | H15: 0 | I15: 0 | J15: 0 | K15: 0 | L15: 0 | M15: 0 | N15: 0 | O15: 0 | P15: 0 | Q15: 4 | R15: 0 | S15: 0 | T15: 0 | U15: 0 | V15: 0 | W15: 4 | X15: 0 | Y15: 0 | Z15: 0 | AA15: 0 | AB15: =IF(Q15=0,0,Q15*VLOOKUP("Инженер инфраструктуры",'Ставки профессий'!$A:$B,2,FALSE))+IF(W15=0,0,W15*VLOOKUP("Проектный менеджер",'Ставки профессий'!$A:$B,2,FALSE))
A16: 2 | B16: Проектирование | D16: 0 | E16: 0 | F16: 0 | G16: 0 | H16: 0 | I16: 0 | J16: 0 | K16: 0 | L16: 0 | M16: 0 | N16: 0 | O16: 0 | P16: 0 | Q16: 0 | R16: 0 | S16: 0 | T16: 0 | U16: 0 | V16: 0 | W16: 0 | X16: 0 | Y16: 0 | Z16: 0 | AA16: 0 | AB16: 0
A17: 2.1 | B17: Архитектурное проектирование | D17: 0 | E17: 0 | F17: 0 | G17: 0 | H17: 0 | I17: 0 | J17: 0 | K17: 0 | L17: 0 | M17: 37 | N17: 0 | O17: 0 | P17: 37 | Q17: 0 | R17: 0 | S17: 0 | T17: 0 | U17: 0 | V17: 0 | W17: 0 | X17: 0 | Y17: 0 | Z17: 0 | AA17: 0 | AB17: =IF(M17=0,0,M17*VLOOKUP("Архитектор ПО",'Ставки профессий'!$A:$B,2,FALSE))+IF(P17=0,0,P17*VLOOKUP("Инженер БД",'Ставки профессий'!$A:$B,2,FALSE))
A18: 2.1.1 | B18: Проектирование трехзвенной архитектуры | D18: 0 | E18: 0 | F18: 0 | G18: 0 | H18: 0 | I18: 0 | J18: 0 | K18: 0 | L18: 0 | M18: 16 | N18: 0 | O18: 0 | P18: 0 | Q18: 0 | R18: 0 | S18: 0 | T18: 0 | U18: 0 | V18: 0 | W18: 0 | X18: 0 | Y18: 0 | Z18: 0 | AA18: 0 | AB18: =IF(M18=0,0,M18*VLOOKUP("Архитектор ПО",'Ставки профессий'!$A:$B,2,FALSE))
A19: 2.1.2 | B19: Проектирование многозонового развертывания | D19: 0 | E19: 0 | F19: 0 | G19: 0 | H19: 0 | I19: 0 | J19: 0 | K19: 0 | L19: 0 | M19: 16 | N19: 0 | O19: 0 | P19: 0 | Q19: 0 | R19: 0 | S19: 0 | T19: 0 | U19: 0 | V19: 0 | W19: 0 | X19: 0 | Y19: 0 | Z19: 0 | AA19: 0 | AB19: =IF(M19=0,0,M19*VLOOKUP("Архитектор ПО",'Ставки профессий'!$A:$B,2,FALSE))
A20: 2.1.3 | B20: Проектирование схемы катастрофоустойчивости | C20: 🔄 | D20: 0 | E20: 0 | F20: 0 | G20: 0 | H20: 0 | I20: 0 | J20: 0 | K20: 0 | L20: 0 | M20: 8 | N20: 0 | O20: 0 | P20: 8 | Q20: 0 | R20: 0 | S20: 0 | T20: 0 | U20: 0 | V20: 0 | W20: 0 | X20: 0 | Y20: 0 | Z20: 0 | AA20: 0 | AB20: =IF(M20=0,0,M20*VLOOKUP("Архитектор ПО",'Ставки профессий'!$A:$B,2,FALSE))+IF(P20=0,0,P20*VLOOKUP("Инженер БД",'Ставки профессий'!$A:$B,2,FALSE))
A21: 2.1.4 | B21: Разработка стратегии резервного копирования | D21: 0 | E21: 0 | F21: 0 | G21: 0 | H21: 0 | I21: 0 | J21: 0 | K21: 0 | L21: 0 | M21: 0 | N21: 0 | O21: 0 | P21: 14 | Q21: 0 | R21: 0 | S21: 0 | T21: 0 | U21: 0 | V21: 0 | W21: 0 | X21: 0 | Y21: 0 | Z21: 0 | AA21: 0 | AB21: =IF(P21=0,0,P21*VLOOKUP("Инженер БД",'Ставки профессий'!$A:$B,2,FALSE))
A22: 2.1.5 | B22: Оформление архитектурной документации | D22: 0 | E22: 0 | F22: 0 | G22: 0 | H22: 0 | I22: 0 | J22: 0 | K22: 0 | L22: 0 | M22: 12 | N22: 0 | O22: 0 | P22: 0 | Q22: 0 | R22: 0 | S22: 0 | T22: 0 | U22: 0 | V22: 0 | W22: 0 | X22: 0 | Y22: 0 | Z22: 0 | AA22: 0 | AB22: =IF(M22=0,0,M22*VLOOKUP("Архитектор ПО",'Ставки профессий'!$A:$B,2,FALSE))
A23: 2.2 | B23: Проектирование подсистемы хранения и обработки | C23: 🔄 | D23: 0 | E23: 0 | F23: 59 | G23: 0 | H23: 0 | I23: 0 | J23: 0 | K23: 0 | L23: 0 | M23: 0 | N23: 0 | O23: 59 | P23: 0 | Q23: 0 | R23: 0 | S23: 0 | T23: 0 | U23: 0 | V23: 0 | W23: 0 | X23: 0 | Y23: 0 | Z23: 0 | AA23: 0 | AB23: =IF(F23=0,0,F23*VLOOKUP("Data Engineer",'Ставки профессий'!$A:$B,2,FALSE))+IF(O23=0,0,O23*VLOOKUP("Архитектор данных",'Ставки профессий'!$A:$B,2,FALSE))
A24: 2.2.1 | B24: Проектирование модели Raw Data Vault | C24: 🔄 | D24: 0 | E24: 0 | F24: 0 | G24: 0 | H24: 0 | I24: 0 | J24: 0 | K24: 0 | L24: 0 | M24: 0 | N24: 0 | O24: 24 | P24: 0 | Q24: 0 | R24: 0 | S24: 0 | T24: 0 | U24: 0 | V24: 0 | W24: 0 | X24: 0 | Y24: 0 | Z24: 0 | AA24: 0 | AB24: =IF(O24=0,0,O24*VLOOKUP("Архитектор данных",'Ставки профессий'!$A:$B,2,FALSE))
A25: 2.2.2 | B25: Проектирование модели Business Data Vault | D25: 0 | E25: 0 | F25: 0 | G25: 0 | H25: 0 | I25: 0 | J25: 0 | K25: 0 | L25: 0 | M25: 0 | N25: 0 | O25: 24 | P25: 0 | Q25: 0 | R25: 0 | S25: 0 | T25: 0 | U25: 0 | V25: 0 | W25: 0 | X25: 0 | Y25: 0 | Z25: 0 | AA25: 0 | AB25: =IF(O25=0,0,O25*VLOOKUP("Архитектор данных",'Ставки профессий'!$A:$B,2,FALSE))
A26: 2.2.3 | B26: Проектирование витрин данных | D26: 0 | E26: 0 | F26: 8 | G26: 0 | H26: 0 | I26: 0 | J26: 0 | K26: 0 | L26: 0 | M26: 0 | N26: 0 | O26: 8 | P26: 0 | Q26: 0 | R26: 0 | S26: 0 | T26: 0 | U26: 0 | V26: 0 | W26: 0 | X26: 0 | Y26: 0 | Z26: 0 | AA26: 0 | AB26: =IF(F26=0,0,F26*VLOOKUP("Data Engineer",'Ставки профессий'!$A:$B,2,FALSE))+IF(O26=0,0,O26*VLOOKUP("Архитектор данных",'Ставки профессий'!$A:$B,2,FALSE))
A27: 2.2.4 | B27: Проектирование ETL-процессов загрузки | C27: 🔄 | D27: 0 | E27: 0 | F27: 32 | G27: 0 | H27: 0 | I27: 0 | J27: 0 | K27: 0 | L27: 0 | M27: 0 | N27: 0 | O27: 0 | P27: 0 | Q27: 0 | R27: 0 | S27: 0 | T27: 0 | U27: 0 | V27: 0 | W27: 0 | X27: 0 | Y27: 0 | Z27: 0 | AA27: 0 | AB27: =IF(F27=0,0,F27*VLOOKUP("Data Engineer",'Ставки профессий'!$A:$B,2,FALSE))
A28: 2.2.5 | B28: Проектирование стратегии репликации и восстановления | D28: 0 | E28: 0 | F28: 11 | G28: 0 | H28: 0 | I28: 0 | J28: 0 | K28: 0 | L28: 0 | M28: 0 | N28: 0 | O28: 11 | P28: 0 | Q28: 0 | R28: 0 | S28: 0 | T28: 0 | U28: 0 | V28: 0 | W28: 0 | X28: 0 | Y28: 0 | Z28: 0 | AA28: 0 | AB28: =IF(F28=0,0,F28*VLOOKUP("Data Engineer",'Ставки профессий'!$A:$B,2,FALSE))+IF(O28=0,0,O28*VLOOKUP("Архитектор данных",'Ставки профессий'!$A:$B,2,FALSE))
A29: 2.3 | B29: Проектирование безопасности и доступа | C29: 🔄 | D29: 0 | E29: 0 | F29: 0 | G29: 0 | H29: 0 | I29: 0 | J29: 0 | K29: 0 | L29: 0 | M29: 0 | N29: 50 | O29: 0 | P29: 0 | Q29: 0 | R29: 0 | S29: 0 | T29: 0 | U29: 0 | V29: 0 | W29: 0 | X29: 0 | Y29: 50 | Z29: 0 | AA29: 0 | AB29: =IF(N29=0,0,N29*VLOOKUP("Архитектор безопасности",'Ставки профессий'!$A:$B,2,FALSE))+IF(Y29=0,0,Y29*VLOOKUP("Специалист ИБ",'Ставки профессий'!$A:$B,2,FALSE))
A30: 2.3.1 | B30: Проектирование модели аутентификации и идентификации | C30: 🔄 | D30: 0 | E30: 0 | F30: 0 | G30: 0 | H30: 0 | I30: 0 | J30: 0 | K30: 0 | L30: 0 | M30: 0 | N30: 6 | O30: 0 | P30: 0 | Q30: 0 | R30: 0 | S30: 0 | T30: 0 | U30: 0 | V30: 0 | W30: 0 | X30: 0 | Y30: 6 | Z30: 0 | AA30: 0 | AB30: =IF(N30=0,0,N30*VLOOKUP("Архитектор безопасности",'Ставки профессий'!$A:$B,2,FALSE))+IF(Y30=0,0,Y30*VLOOKUP("Специалист ИБ",'Ставки профессий'!$A:$B,2,FALSE))
A31: 2.3.2 | B31: Проектирование ролевой модели и системы авторизации | D31: 0 | E31: 0 | F31: 0 | G31: 0 | H31: 0 | I31: 0 | J31: 0 | K31: 0 | L31: 0 | M31: 0 | N31: 12 | O31: 0 | P31: 0 | Q31: 0 | R31: 0 | S31: 0 | T31: 0 | U31: 0 | V31: 0 | W31: 0 | X31: 0 | Y31: 12 | Z31: 0 | AA31: 0 | AB31: =IF(N31=0,0,N31*VLOOKUP("Архитектор безопасности",'Ставки профессий'!$A:$B,2,FALSE))+IF(Y31=0,0,Y31*VLOOKUP("Специалист ИБ",'Ставки профессий'!$A:$B,2,FALSE))
A32: 2.3.3 | B32: Проектирование системы категоризации данных | C32: 🔄 | D32: 0 | E32: 0 | F32: 0 | G32: 0 | H32: 0 | I32: 0 | J32: 0 | K32: 0 | L32: 0 | M32: 0 | N32: 8 | O32: 0 | P32: 0 | Q32: 0 | R32: 0 | S32: 0 | T32: 0 | U32: 0 | V32: 0 | W32: 0 | X32: 0 | Y32: 8 | Z32: 0 | AA32: 0 | AB32: =IF(N32=0,0,N32*VLOOKUP("Архитектор безопасности",'Ставки профессий'!$A:$B,2,FALSE))+IF(Y32=0,0,Y32*VLOOKUP("Специалист ИБ",'Ставки профессий'!$A:$B,2,FALSE))
A33: 2.3.4 | B33: Проектирование механизма гранулированного доступа | D33: 0 | E33: 0 | F33: 0 | G33: 0 | H33: 0 | I33: 0 | J33: 0 | K33: 0 | L33: 0 | M33: 0 | N33: 8 | O33: 0 | P33: 0 | Q33: 0 | R33: 0 | S33: 0 | T33: 0 | U33: 0 | V33: 0 | W33: 0 | X33: 0 | Y33: 8 | Z33: 0 | AA33: 0 | AB33: =IF(N33=0,0,N33*VLOOKUP("Архитектор безопасности",'Ставки профессий'!$A:$B,2,FALSE))+IF(Y33=0,0,Y33*VLOOKUP("Специалист ИБ",'Ставки профессий'!$A:$B,2,FALSE))
A34: 2.3.5 | B34: Проектирование подсистемы аудита и контроля действий | D34: 0 | E34: 0 | F34: 0 | G34: 0 | H34: 0 | I34: 0 | J34: 0 | K34: 0 | L34: 0 | M34: 0 | N34: 8 | O34: 0 | P34: 0 | Q34: 0 | R34: 0 | S34: 0 | T34: 0 | U34: 0 | V34: 0 | W34: 0 | X34: 0 | Y34: 8 | Z34: 0 | AA34: 0 | AB34: =IF(N34=0,0,N34*VLOOKUP("Архитектор безопасности",'Ставки профессий'!$A:$B,2,FALSE))+IF(Y34=0,0,Y34*VLOOKUP("Специалист ИБ",'Ставки профессий'!$A:$B,2,FALSE))
A35: 2.3.6 | B35: Формирование итоговой модели безопасности и политик доступа | D35: 0 | E35: 0 | F35: 0 | G35: 0 | H35: 0 | I35: 0 | J35: 0 | K35: 0 | L35: 0 | M35: 0 | N35: 8 | O35: 0 | P35: 0 | Q35: 0 | R35: 0 | S35: 0 | T35: 0 | U35: 0 | V35: 0 | W35: 0 | X35: 0 | Y35: 8 | Z35: 0 | AA35: 0 | AB35: =IF(N35=0,0,N35*VLOOKUP("Архитектор безопасности",'Ставки профессий'!$A:$B,2,FALSE))+IF(Y35=0,0,Y35*VLOOKUP("Специалист ИБ",'Ставки профессий'!$A:$B,2,FALSE))
A36: 2.4 | B36: Проектирование интеграций | C36: 🔄 | D36: 0 | E36: 30 | F36: 0 | G36: 0 | H36: 0 | I36: 0 | J36: 0 | K36: 0 | L36: 0 | M36: 0 | N36: 0 | O36: 0 | P36: 0 | Q36: 0 | R36: 0 | S36: 0 | T36: 0 | U36: 30 | V36: 0 | W36: 0 | X36: 0 | Y36: 0 | Z36: 0 | AA36: 0 | AB36: =IF(E36=0,0,E36*VLOOKUP("Backend-разработчик",'Ставки профессий'!$A:$B,2,FALSE))+IF(U36=0,0,U36*VLOOKUP("Интеграционный архитектор",'Ставки профессий'!$A:$B,2,FALSE))
A37: 2.4.1 | B37: Проектирование интеграционной архитектуры | C37: 🔄 | D37: 0 | E37: 0 | F37: 0 | G37: 0 | H37: 0 | I37: 0 | J37: 0 | K37: 0 | L37: 0 | M37: 0 | N37: 0 | O37: 0 | P37: 0 | Q37: 0 | R37: 0 | S37: 0 | T37: 0 | U37: 4 | V37: 0 | W37: 0 | X37: 0 | Y37: 0 | Z37: 0 | AA37: 0 | AB37: =IF(U37=0,0,U37*VLOOKUP("Интеграционный архитектор",'Ставки профессий'!$A:$B,2,FALSE))
A38: 2.4.2 | B38: Проектирование интеграции с СУБД и хранилищами данных | D38: 0 | E38: 6 | F38: 0 | G38: 0 | H38: 0 | I38: 0 | J38: 0 | K38: 0 | L38: 0 | M38: 0 | N38: 0 | O38: 0 | P38: 0 | Q38: 0 | R38: 0 | S38: 0 | T38: 0 | U38: 6 | V38: 0 | W38: 0 | X38: 0 | Y38: 0 | Z38: 0 | AA38: 0 | AB38: =IF(E38=0,0,E38*VLOOKUP("Backend-разработчик",'Ставки профессий'!$A:$B,2,FALSE))+IF(U38=0,0,U38*VLOOKUP("Интеграционный архитектор",'Ставки профессий'!$A:$B,2,FALSE))
A39: 2.4.3 | B39: Проектирование интеграции порталов управления | C39: 🔄 | D39: 0 | E39: 4 | F39: 0 | G39: 0 | H39: 0 | I39: 0 | J39: 0 | K39: 0 | L39: 0 | M39: 0 | N39: 0 | O39: 0 | P39: 0 | Q39: 0 | R39: 0 | S39: 0 | T39: 0 | U39: 0 | V39: 0 | W39: 0 | X39: 0 | Y39: 0 | Z39: 0 | AA39: 0 | AB39: =IF(E39=0,0,E39*VLOOKUP("Backend-разработчик",'Ставки профессий'!$A:$B,2,FALSE))
A40: 2.4.4 | B40: Проектирование потоков передачи событий ИБ | C40: 🔄 | D40: 0 | E40: 0 | F40: 0 | G40: 0 | H40: 0 | I40: 0 | J40: 0 | K40: 0 | L40: 0 | M40: 0 | N40: 0 | O40: 0 | P40: 0 | Q40: 0 | R40: 0 | S40: 0 | T40: 0 | U40: 16 | V40: 0 | W40: 0 | X40: 0 | Y40: 0 | Z40: 0 | AA40: 0 | AB40: =IF(U40=0,0,U40*VLOOKUP("Интеграционный архитектор",'Ставки профессий'!$A:$B,2,FALSE))
...

Sheet Ставки профессий
A1: Профессия (роль) | B1: Ставка в час (руб)
A2: BI-разработчик | B2: 1000
A3: Backend-разработчик | B3: 1000
A4: Data Engineer | B4: 1000
A5: DevOps | B5: 1000
A6: Pentester | B6: 1000
A7: Performance Engineer | B7: 1000
A8: QA-инженер | B8: 1000
A9: Администратор БД | B9: 1400
A10: Архитектор | B10: 2000
A11: Архитектор ПО | B11: 1000
A12: Архитектор безопасности | B12: 1000
A13: Архитектор данных | B13: 1000
... A38: Тестировщик (QA) | B38: 800
A41: Примечание: Измените ставки на этом листе для автоматического пересчета стоимости на листе WBS.

Sheet Диаграмма Гантта
A1: ID | B1: Название работы | C1: Неделя | D1: Дней | E1: W1 | F1: W2 | G1: W3 | H1: W4 | I1: W5 | J1: W6 | K1: W7 | L1: W8 | M1: W9 | N1: W10 | O1: W11 | P1: W12 | Q1: W13 | R1: W14 | S1: W15
A2: 1 | B2: Планирование и анализ | C2: 1 | D2: 13
A3: 1.1 | B3: Анализ требований и декомпозиция 🔄 | C3: 1 | D3: 13
A4: 1.2 | B4: Планирование инфраструктуры и ресурсов 🔄 | C4: 1 | D4: 5
A5: 1.1.1 | B5: Сбор и анализ функциональных требований 🔄 | C5: 1 | D5: 2
A6: 1.1.2 | B6: Анализ нефункциональных требований и ограничений 🔄 | C6: 1 | D6: 2
A7: 1.1.3 | B7: Формирование структуры ТЗ согласно 644-П 🔄 | C7: 1 | D7: 2
A8: 1.2.1 | B8: Анализ требований к инфраструктуре зон развертывания 🔄 | C8: 1 | D8: 1
A9: 1.2.4 | B9: Составление карты компетенций поддержки 🔄 | C9: 1 | D9: 2
A10: 1.2.2 | B10: Расчет ресурсов для обеспечения RPO/RTO | C10: 1 | D10: 2
A11: 1.1.4 | B11: Разработка разделов ТЗ | C11: 1 | D11: 4
A12: 1.2.3 | B12: Планирование катастрофоустойчивости | C12: 1 | D12: 1
A13: 1.2.5 | B13: Формирование плана инфраструктуры | C13: 1 | D13: 1
... A117: 5.2.6 | B117: Проведение приемочных испытаний развертывания | C117: 15 | D117: 2
A120: Легенда:
A121: ■ | B121: Фаза
A122: ■ | B122: Пакет работ (последовательно)
A123: ■ | B123: Пакет работ (параллельно) 🔄
A124: ■ | B124: Задача (последовательно)
A125: ■ | B125: Задача (параллельно) 🔄
A127: Примечание: W = рабочая неделя (5 дней). 🔄 = может выполняться параллельно с другими задачами. Параллельные задачи начинаются одновременно.
